<mujoco model="g1-box-tower-of-hanoi">
  <compiler angle="radian" meshdir="stl" />
  <option iterations="50" solver="Newton" timestep="0.0005" gravity="0 0 -9.80665" impratio="20" cone="elliptic">
    <flag midphase="disable"/>
  </option>
  <size nconmax="-1" />
  <asset>
    <material name="collision" rgba="0.1 0.5 0.9 0.4"/>
    <texture name="good_color" file="../digit_sim/floor1.png" type="2d"/>
    <material name="plane" reflectance="0.000000" texrepeat="2 2" texture="good_color" texuniform="true"/>
    <material name="robot" rgba="0.25 0.8 0.8 1"/>
    <material name="obstacle" rgba="0.2 0.6 0.2 1"/>
    <texture builtin="checker" name="plane" height="512" width="512" rgb1="0.2 0.2 0.2" rgb2="0.3 0.3 0.3" type="2d"/>
    <texture name="skybox" type="skybox" builtin="gradient" rgb1=".16 .16 .8" rgb2="0 0 0" width="800" height="800" mark="random" markrgb="1 1 1"/>
  </asset>
  <default>
    <default class="collision">
      <geom conaffinity="1" condim="3" contype="1" group="3"/>
    </default>
    <default class="obstacle">
      <geom material="obstacle" condim="3" contype="8" conaffinity="15" user="1"/>
    </default>
    <default class="torso_motor">
      <joint damping="0.05" armature="0.01" frictionloss="0.2"/>
    </default>
    <default class="leg_motor">
      <joint damping="0.05" armature="0.01" frictionloss="0.2"/>
    </default>
    <default class="ankle_motor">
      <joint damping="0.05" armature="0.01" frictionloss="0.2"/>
    </default>
    <default class="arm_motor">
      <joint damping="0.05" armature="0.01" frictionloss="0.2"/>
    </default>
    <default class="wrist_motor">
      <joint damping="0.05" armature="0.01" frictionloss="0.1"/>
    </default>
    <default class="g1">
      <geom type="mesh"/>
      <default class="visual">
        <geom contype="0" conaffinity="0" group="1"/>
      </default>
    </default>
    <equality solimp="0.9 0.95 0.001 0.1 2" solref="0.001 1.1" />
    <geom conaffinity="0" condim="1" contype="0" solref="0.02 1" />
    <joint solreflimit="0.001 1" />
  </default>

  <asset>
    <mesh name="pelvis" file="pelvis.STL" />
    <mesh name="pelvis_contour_link" file="pelvis_contour_link.STL" />
    <mesh name="left_hip_pitch_link" file="left_hip_pitch_link.STL" />
    <mesh name="left_hip_roll_link" file="left_hip_roll_link.STL" />
    <mesh name="left_hip_yaw_link" file="left_hip_yaw_link.STL" />
    <mesh name="left_knee_link" file="left_knee_link.STL" />
    <mesh name="left_ankle_pitch_link" file="left_ankle_pitch_link.STL" />
    <mesh name="left_ankle_roll_link" file="left_ankle_roll_link.STL" />
    <mesh name="right_hip_pitch_link" file="right_hip_pitch_link.STL" />
    <mesh name="right_hip_roll_link" file="right_hip_roll_link.STL" />
    <mesh name="right_hip_yaw_link" file="right_hip_yaw_link.STL" />
    <mesh name="right_knee_link" file="right_knee_link.STL" />
    <mesh name="right_ankle_pitch_link" file="right_ankle_pitch_link.STL" />
    <mesh name="right_ankle_roll_link" file="right_ankle_roll_link.STL" />
    <mesh name="waist_yaw_link" file="waist_yaw_link.STL" />
    <mesh name="waist_roll_link" file="waist_roll_link.STL" />
    <mesh name="torso_link" file="torso_link.STL" />
    <mesh name="logo_link" file="logo_link.STL" />
    <mesh name="head_link" file="head_link.STL" />
    <mesh name="waist_support_link" file="waist_support_link.STL" />
    <mesh name="left_shoulder_pitch_link" file="left_shoulder_pitch_link.STL" />
    <mesh name="left_shoulder_roll_link" file="left_shoulder_roll_link.STL" />
    <mesh name="left_shoulder_yaw_link" file="left_shoulder_yaw_link.STL" />
    <mesh name="left_elbow_link" file="left_elbow_link.STL" />
    <mesh name="left_wrist_roll_link" file="left_wrist_roll_link.STL" />
    <mesh name="left_wrist_pitch_link" file="left_wrist_pitch_link.STL" />
    <mesh name="left_wrist_yaw_link" file="left_wrist_yaw_link.STL" />
    <mesh name="left_rubber_hand" file="left_rubber_hand.STL" />
    <mesh name="right_shoulder_pitch_link" file="right_shoulder_pitch_link.STL" />
    <mesh name="right_shoulder_roll_link" file="right_shoulder_roll_link.STL" />
    <mesh name="right_shoulder_yaw_link" file="right_shoulder_yaw_link.STL" />
    <mesh name="right_elbow_link" file="right_elbow_link.STL" />
    <mesh name="right_wrist_roll_link" file="right_wrist_roll_link.STL" />
    <mesh name="right_wrist_pitch_link" file="right_wrist_pitch_link.STL" />
    <mesh name="right_wrist_yaw_link" file="right_wrist_yaw_link.STL" />
    <mesh name="right_rubber_hand" file="right_rubber_hand.STL" />
  </asset>

  <worldbody>
    <geom name="floor" type="plane" material="plane" size="0 0 1" contype="1" conaffinity="127" condim="3" friction="0.7 0.01 0.005" pos="0 0 0" priority="100" />
    <light mode="trackcom" pos="0 0 5" dir="0 0 -1"/>
    <light directional="true" pos="0 0 3" dir="0 0 -1" diffuse="0.5 0.5 0.5" specular="0 0 0"/>
    <body name="pelvis" pos="0 0 0.8" childclass="g1">
      <site name="imu" size="0.01" pos="0.0 0.0 0.0" />
      <inertial pos="0 0 -0.07605" quat="1 0 -0.000399148 0" mass="3.813"
        diaginertia="0.010549 0.0093089 0.0079184" />
      <joint name="floating_base_joint" type="free" limited="false" actuatorfrclimited="false" />
      <geom class="visual" mesh="pelvis" rgba="0.2 0.2 0.2 1"/>
      <geom class="collision" mesh="pelvis"/>
      <geom class="visual" mesh="pelvis_contour_link" rgba="0.7 0.7 0.7 1"/>
      <geom class="collision" mesh="pelvis_contour_link"/>
      <body name="left_hip_pitch_link" pos="0 0.064452 -0.1027">
        <inertial pos="0.002741 0.047791 -0.02606" quat="0.954862 0.293964 0.0302556 0.030122"
          mass="1.35" diaginertia="0.00181517 0.00153422 0.00116212" />
        <joint name="left_hip_pitch_joint" pos="0 0 0" axis="0 1 0" range="-2.5307 2.8798"
          actuatorfrcrange="-88 88" class="leg_motor" />
        <geom class="visual" mesh="left_hip_pitch_link" rgba="0.2 0.2 0.2 1"/>
        <geom class="collision" mesh="left_hip_pitch_link"/>
        <body name="left_hip_roll_link" pos="0 0.052 -0.030465" quat="0.996179 0 -0.0873386 0">
          <inertial pos="0.029812 -0.001045 -0.087934"
            quat="0.977808 -1.97119e-05 0.205576 -0.0403793" mass="1.52"
            diaginertia="0.00254986 0.00241169 0.00148755" />
          <joint name="left_hip_roll_joint" pos="0 0 0" axis="1 0 0" range="-0.5236 2.9671"
            actuatorfrcrange="-88 88" class="leg_motor" />
          <geom class="visual" mesh="left_hip_roll_link" rgba="0.7 0.7 0.7 1"/>
          <geom class="collision" mesh="left_hip_roll_link"/>
          <body name="left_hip_yaw_link" pos="0.025001 0 -0.12412">
            <inertial pos="-0.057709 -0.010981 -0.15078" quat="0.600598 0.15832 0.223482 0.751181"
              mass="1.702" diaginertia="0.00776166 0.00717575 0.00160139" />
            <joint name="left_hip_yaw_joint" pos="0 0 0" axis="0 0 1" range="-2.7576 2.7576"
              actuatorfrcrange="-88 88" class="leg_motor" />
            <geom class="visual" mesh="left_hip_yaw_link" rgba="0.7 0.7 0.7 1"/>
            <geom class="collision" mesh="left_hip_yaw_link"/>
            <body name="left_knee_link" pos="-0.078273 0.0021489 -0.17734"
              quat="0.996179 0 0.0873386 0">
              <inertial pos="0.005457 0.003964 -0.12074"
                quat="0.923418 -0.0327699 0.0158246 0.382067" mass="1.932"
                diaginertia="0.0113804 0.0112778 0.00146458" />
              <joint name="left_knee_joint" pos="0 0 0" axis="0 1 0" range="-0.087267 2.8798"
                actuatorfrcrange="-139 139" class="leg_motor" />
              <geom class="visual" mesh="left_knee_link" rgba="0.7 0.7 0.7 1"/>
              <geom class="collision" mesh="left_knee_link"/>
              <body name="left_ankle_pitch_link" pos="0 -9.4445e-05 -0.30001">
                <inertial pos="-0.007269 0 0.011137" quat="0.603053 0.369225 0.369225 0.603053"
                  mass="0.074" diaginertia="1.89e-05 1.40805e-05 6.9195e-06" />
                <joint name="left_ankle_pitch_joint" pos="0 0 0" axis="0 1 0"
                  range="-0.87267 0.5236" actuatorfrcrange="-50 50"  class="ankle_motor"/>
                <geom class="visual" mesh="left_ankle_pitch_link" rgba="0.7 0.7 0.7 1"/>
                <geom class="collision" mesh="left_ankle_pitch_link"/>
                <body name="left_ankle_roll_link" pos="0 0 -0.017558">
                  <inertial pos="0.026505 0 -0.016425"
                    quat="-0.000481092 0.728482 -0.000618967 0.685065" mass="0.608"
                    diaginertia="0.00167218 0.0016161 0.000217621" />
                  <joint name="left_ankle_roll_joint" pos="0 0 0" axis="1 0 0"
                    range="-0.2618 0.2618" actuatorfrcrange="-50 50" class="ankle_motor"/>
                  <geom class="visual" mesh="left_ankle_roll_link" rgba="0.2 0.2 0.2 1"/>
                  <geom class="collision" mesh="left_ankle_roll_link"/>
                  <geom size="0.005" pos="-0.05 0.025 -0.03" rgba="0.2 0.2 0.2 1" class="collision"/>
                  <geom size="0.005" pos="-0.05 -0.025 -0.03" rgba="0.2 0.2 0.2 1" class="collision"/>
                  <geom size="0.005" pos="0.12 0.03 -0.03" rgba="0.2 0.2 0.2 1" class="collision"/>
                  <geom size="0.005" pos="0.12 -0.03 -0.03" rgba="0.2 0.2 0.2 1" class="collision"/>
                </body>
              </body>
            </body>
          </body>
        </body>
      </body>
      <body name="right_hip_pitch_link" pos="0 -0.064452 -0.1027">
        <inertial pos="0.002741 -0.047791 -0.02606" quat="0.954862 -0.293964 0.0302556 -0.030122"
          mass="1.35" diaginertia="0.00181517 0.00153422 0.00116212" />
        <joint name="right_hip_pitch_joint" pos="0 0 0" axis="0 1 0" range="-2.5307 2.8798"
          actuatorfrcrange="-88 88" class="leg_motor" />
        <geom class="visual" mesh="right_hip_pitch_link" rgba="0.2 0.2 0.2 1"/>
        <geom class="collision" mesh="right_hip_pitch_link"/>
        <body name="right_hip_roll_link" pos="0 -0.052 -0.030465" quat="0.996179 0 -0.0873386 0">
          <inertial pos="0.029812 0.001045 -0.087934" quat="0.977808 1.97119e-05 0.205576 0.0403793"
            mass="1.52" diaginertia="0.00254986 0.00241169 0.00148755" />
          <joint name="right_hip_roll_joint" pos="0 0 0" axis="1 0 0" range="-2.9671 0.5236"
            actuatorfrcrange="-88 88" class="leg_motor" />
          <geom class="visual" mesh="right_hip_roll_link" rgba="0.7 0.7 0.7 1"/>
          <geom class="collision" mesh="right_hip_roll_link"/>
          <body name="right_hip_yaw_link" pos="0.025001 0 -0.12412">
            <inertial pos="-0.057709 0.010981 -0.15078" quat="0.751181 0.223482 0.15832 0.600598"
              mass="1.702" diaginertia="0.00776166 0.00717575 0.00160139" />
            <joint name="right_hip_yaw_joint" pos="0 0 0" axis="0 0 1" range="-2.7576 2.7576"
              actuatorfrcrange="-88 88" class="leg_motor" />
            <geom class="visual" mesh="right_hip_yaw_link" rgba="0.7 0.7 0.7 1"/>
            <geom class="collision" mesh="right_hip_yaw_link"/>
            <body name="right_knee_link" pos="-0.078273 -0.0021489 -0.17734"
              quat="0.996179 0 0.0873386 0">
              <inertial pos="0.005457 -0.003964 -0.12074"
                quat="0.923439 0.0345276 0.0116333 -0.382012" mass="1.932"
                diaginertia="0.011374 0.0112843 0.00146452" />
              <joint name="right_knee_joint" pos="0 0 0" axis="0 1 0" range="-0.087267 2.8798"
                actuatorfrcrange="-139 139" class="leg_motor" />
              <geom class="visual" mesh="right_knee_link" rgba="0.7 0.7 0.7 1"/>
              <geom class="collision" mesh="right_knee_link"/>
              <body name="right_ankle_pitch_link" pos="0 9.4445e-05 -0.30001">
                <inertial pos="-0.007269 0 0.011137" quat="0.603053 0.369225 0.369225 0.603053"
                  mass="0.074" diaginertia="1.89e-05 1.40805e-05 6.9195e-06" />
                <joint name="right_ankle_pitch_joint" pos="0 0 0" axis="0 1 0"
                  range="-0.87267 0.5236" actuatorfrcrange="-50 50" class="ankle_motor" />
                <geom class="visual" mesh="right_ankle_pitch_link" rgba="0.7 0.7 0.7 1"/>
                <geom class="collision" mesh="right_ankle_pitch_link"/>
                <body name="right_ankle_roll_link" pos="0 0 -0.017558">
                  <inertial pos="0.026505 0 -0.016425"
                    quat="0.000481092 0.728482 0.000618967 0.685065" mass="0.608"
                    diaginertia="0.00167218 0.0016161 0.000217621" />
                  <joint name="right_ankle_roll_joint" pos="0 0 0" axis="1 0 0"
                    range="-0.2618 0.2618" actuatorfrcrange="-50 50" class="ankle_motor" />
                  <geom class="visual" mesh="right_ankle_roll_link" rgba="0.2 0.2 0.2 1"/>
                  <geom class="collision" mesh="right_ankle_roll_link"/>
                  <geom size="0.005" pos="-0.05 0.025 -0.03" rgba="0.2 0.2 0.2 1" class="collision"/>
                  <geom size="0.005" pos="-0.05 -0.025 -0.03" rgba="0.2 0.2 0.2 1" class="collision"/>
                  <geom size="0.005" pos="0.12 0.03 -0.03" rgba="0.2 0.2 0.2 1" class="collision"/>
                  <geom size="0.005" pos="0.12 -0.03 -0.03" rgba="0.2 0.2 0.2 1" class="collision"/>
                  <site name="right-foot-mid" type="sphere" pos="0 0 -0.03" size="0.005" rgba="0.7 0.2 0.1 0.0"/>
                </body>
              </body>
            </body>
          </body>
        </body>
      </body>
      <body name="waist_yaw_link">
        <inertial pos="0.003964 0 0.018769" quat="-0.0178291 0.628464 0.0282471 0.777121"
          mass="0.244" diaginertia="0.000158561 0.000124229 9.67669e-05" />
        <joint name="waist_yaw_joint" pos="0 0 0" axis="0 0 1" range="-2.618 2.618"
          actuatorfrcrange="-88 88" class="torso_motor"/>
        <geom class="visual" mesh="waist_yaw_link" rgba="0.7 0.7 0.7 1"/>
        <geom class="collision" mesh="waist_yaw_link"/>
        <body name="waist_roll_link" pos="-0.0039635 0 0.035">
          <inertial pos="0 -0.000236 0.010111" quat="0.99979 0.020492 0 0" mass="0.047"
            diaginertia="7.515e-06 6.40206e-06 3.98394e-06" />
          <joint name="waist_roll_joint" pos="0 0 0" axis="1 0 0" range="-0.52 0.52"
            actuatorfrcrange="-50 50" class="torso_motor"/>
          <geom class="visual" mesh="waist_roll_link" rgba="0.7 0.7 0.7 1"/>
          <geom class="collision" mesh="waist_roll_link"/>
          <site name="secondary_imu" size="0.01" pos="-0.03959 -0.00224 0.13792"/>
          <body name="torso_link" pos="0 0 0.019">
            <inertial pos="0.00331658 0.000261533 0.179856"
              quat="0.999831 0.000376204 0.0179895 -0.00377704" mass="9.598"
              diaginertia="0.12407 0.111951 0.0325382" />
            <joint name="waist_pitch_joint" pos="0 0 0" axis="0 1 0" range="-0.52 0.52"
              actuatorfrcrange="-50 50" class="torso_motor"/>
            <geom class="visual" mesh="torso_link" rgba="0.7 0.7 0.7 1"/>
            <geom class="collision" mesh="torso_link"/>
            <geom class="visual" pos="0.0039635 0 -0.054" quat="1 0 0 0" mesh="logo_link" rgba="0.2 0.2 0.2 1"/>
            <geom class="collision" pos="0.0039635 0 -0.054" quat="1 0 0 0" mesh="logo_link"/>
            <geom class="visual" pos="0.0039635 0 -0.054" mesh="head_link" rgba="0.2 0.2 0.2 1"/>
            <geom class="collision" pos="0.0039635 0 -0.054" mesh="head_link"/>
            <geom class="visual" pos="0.0039635 0 -0.054" quat="1 0 0 0" mesh="waist_support_link" rgba="0.7 0.7 0.7 1"/>
            <geom class="collision" pos="0.0039635 0 -0.054" quat="1 0 0 0" mesh="waist_support_link"/>
            <body name="left_shoulder_pitch_link" pos="0.0039563 0.10022 0.23778"
              quat="0.990264 0.139201 1.38722e-05 -9.86868e-05">
              <inertial pos="0 0.035892 -0.011628" quat="0.654152 0.0130458 -0.326267 0.68225"
                mass="0.718" diaginertia="0.000465864 0.000432842 0.000406394" />
              <joint name="left_shoulder_pitch_joint" pos="0 0 0" axis="0 1 0"
                range="-3.0892 2.6704" actuatorfrcrange="-25 25" class="arm_motor" />
              <geom class="visual" mesh="left_shoulder_pitch_link" rgba="0.7 0.7 0.7 1"/>
              <geom class="collision" mesh="left_shoulder_pitch_link"/>
              <geom size="0.03 0.025" pos="0 0.04 -0.01" quat="0.707107 0 0.707107 0"
                type="cylinder" rgba="0.7 0.7 0.7 1" />
              <body name="left_shoulder_roll_link" pos="0 0.038 -0.013831"
                quat="0.990268 -0.139172 0 0">
                <inertial pos="-0.000227 0.00727 -0.063243"
                  quat="0.701256 -0.0196223 -0.00710317 0.712604" mass="0.643"
                  diaginertia="0.000691311 0.000618011 0.000388977" />
                <joint name="left_shoulder_roll_joint" pos="0 0 0" axis="1 0 0"
                  range="-1.5882 2.2515" actuatorfrcrange="-25 25" class="arm_motor" />
                <geom class="visual" mesh="left_shoulder_roll_link" rgba="0.7 0.7 0.7 1"/>
                <geom class="collision" mesh="left_shoulder_roll_link"/>
                <geom size="0.03 0.015" pos="-0.004 0.006 -0.053" type="cylinder"
                  rgba="0.7 0.7 0.7 1" />
                <body name="left_shoulder_yaw_link" pos="0 0.00624 -0.1032">
                  <inertial pos="0.010773 -0.002949 -0.072009"
                    quat="0.716879 -0.0964829 -0.0679942 0.687134" mass="0.734"
                    diaginertia="0.00106187 0.00103217 0.000400661" />
                  <joint name="left_shoulder_yaw_joint" pos="0 0 0" axis="0 0 1"
                    range="-2.618 2.618" actuatorfrcrange="-25 25" class="arm_motor" />
                  <geom class="visual" mesh="left_shoulder_yaw_link" rgba="0.7 0.7 0.7 1"/>
                  <geom class="collision" mesh="left_shoulder_yaw_link"/>
                  <body name="left_elbow_link" pos="0.015783 0 -0.080518">
                    <inertial pos="0.064956 0.004454 -0.010062"
                      quat="0.541765 0.636132 0.388821 0.388129" mass="0.6"
                      diaginertia="0.000443035 0.000421612 0.000259353" />
                    <joint name="left_elbow_joint" pos="0 0 0" axis="0 1 0" range="-1.0472 2.0944"
                      actuatorfrcrange="-25 25" class="arm_motor" />
                    <geom class="visual" mesh="left_elbow_link" rgba="0.7 0.7 0.7 1"/>
                    <geom class="collision" mesh="left_elbow_link"/>
                    <site name="left-hand" type="sphere" pos="0.1 0 -0.01" size="0.01" rgba="0.7 0.2 0.1 0.0"/>
                    <body name="left_wrist_roll_link" pos="0.1 0.00188791 -0.01">
                      <inertial pos="0.0171394 0.000537591 4.8864e-07"
                        quat="0.575338 0.411667 -0.574906 0.411094" mass="0.085445"
                        diaginertia="5.48211e-05 4.96646e-05 3.57798e-05" />
                      <joint name="left_wrist_roll_joint" pos="0 0 0" axis="1 0 0"
                        range="-1.97222 1.97222" actuatorfrcrange="-25 25" class="arm_motor" />
                      <geom class="visual" mesh="left_wrist_roll_link" rgba="0.7 0.7 0.7 1"/>
                      <geom class="collision" mesh="left_wrist_roll_link"/>
                      <body name="left_wrist_pitch_link" pos="0.038 0 0">
                        <inertial pos="0.0229999 -0.00111685 -0.00111658"
                          quat="0.249998 0.661363 0.293036 0.643608" mass="0.48405"
                          diaginertia="0.000430353 0.000429873 0.000164648" />
                        <joint name="left_wrist_pitch_joint" pos="0 0 0" axis="0 1 0"
                          range="-1.61443 1.61443" actuatorfrcrange="-5 5" class="wrist_motor" />
                        <geom class="visual" mesh="left_wrist_pitch_link" rgba="0.7 0.7 0.7 1"/>
                        <geom class="collision" mesh="left_wrist_pitch_link"/>
                        <body name="left_wrist_yaw_link" pos="0.046 0 0">
                          <inertial pos="0.0708244 0.000191745 0.00161742"
                            quat="0.510571 0.526295 0.468078 0.493188" mass="0.254576"
                            diaginertia="0.000646113 0.000559993 0.000147566" />
                          <joint name="left_wrist_yaw_joint" pos="0 0 0" axis="0 0 1"
                            range="-1.61443 1.61443" actuatorfrcrange="-5 5" class="wrist_motor" />
                          <geom class="visual" mesh="left_wrist_yaw_link" rgba="0.7 0.7 0.7 1"/>
                          <geom class="collision" mesh="left_wrist_yaw_link"/>
                          <geom class="visual" pos="0.0415 0.003 0" quat="1 0 0 0" mesh="left_rubber_hand" rgba="0.7 0.7 0.7 1"/>
                          <geom class="collision" pos="0.0415 0.003 0" quat="1 0 0 0" mesh="left_rubber_hand"/>
                        </body>
                      </body>
                    </body>
                  </body>
                </body>
              </body>
            </body>
            <body name="right_shoulder_pitch_link" pos="0.0039563 -0.10021 0.23778"
              quat="0.990264 -0.139201 1.38722e-05 9.86868e-05">
              <inertial pos="0 -0.035892 -0.011628" quat="0.68225 -0.326267 0.0130458 0.654152"
                mass="0.718" diaginertia="0.000465864 0.000432842 0.000406394" />
              <joint name="right_shoulder_pitch_joint" pos="0 0 0" axis="0 1 0"
                range="-3.0892 2.6704" actuatorfrcrange="-25 25" class="arm_motor" />
              <geom class="visual" mesh="right_shoulder_pitch_link" rgba="0.7 0.7 0.7 1"/>
              <geom class="collision" mesh="right_shoulder_pitch_link"/>
              <geom size="0.03 0.025" pos="0 -0.04 -0.01" quat="0.707107 0 0.707107 0"
                type="cylinder" rgba="0.7 0.7 0.7 1" />
              <body name="right_shoulder_roll_link" pos="0 -0.038 -0.013831"
                quat="0.990268 0.139172 0 0">
                <inertial pos="-0.000227 -0.00727 -0.063243"
                  quat="0.712604 -0.00710317 -0.0196223 0.701256" mass="0.643"
                  diaginertia="0.000691311 0.000618011 0.000388977" />
                <joint name="right_shoulder_roll_joint" pos="0 0 0" axis="1 0 0"
                  range="-2.2515 1.5882" actuatorfrcrange="-25 25" class="arm_motor" />
                <geom class="visual" mesh="right_shoulder_roll_link" rgba="0.7 0.7 0.7 1"/>
                <geom class="collision" mesh="right_shoulder_roll_link"/>
                <geom size="0.03 0.015" pos="-0.004 -0.006 -0.053" type="cylinder"
                  rgba="0.7 0.7 0.7 1" />
                <body name="right_shoulder_yaw_link" pos="0 -0.00624 -0.1032">
                  <inertial pos="0.010773 0.002949 -0.072009"
                    quat="0.687134 -0.0679942 -0.0964829 0.716879" mass="0.734"
                    diaginertia="0.00106187 0.00103217 0.000400661" />
                  <joint name="right_shoulder_yaw_joint" pos="0 0 0" axis="0 0 1"
                    range="-2.618 2.618" actuatorfrcrange="-25 25" class="arm_motor" />
                  <geom class="visual" mesh="right_shoulder_yaw_link" rgba="0.7 0.7 0.7 1"/>
                  <geom class="collision" mesh="right_shoulder_yaw_link"/>
                  <body name="right_elbow_link" pos="0.015783 0 -0.080518">
                    <inertial pos="0.064956 -0.004454 -0.010062"
                      quat="0.388129 0.388821 0.636132 0.541765" mass="0.6"
                      diaginertia="0.000443035 0.000421612 0.000259353" />
                    <joint name="right_elbow_joint" pos="0 0 0" axis="0 1 0" range="-1.0472 2.0944"
                      actuatorfrcrange="-25 25" class="arm_motor" />
                    <geom class="visual" mesh="right_elbow_link" rgba="0.7 0.7 0.7 1"/>
                    <geom class="collision" mesh="right_elbow_link"/>
                    <site name="right-hand" type="sphere" pos="0.1 0 -0.01" size="0.01" rgba="0.7 0.2 0.1 0.0"/>
                    <body name="right_wrist_roll_link" pos="0.1 -0.00188791 -0.01">
                      <inertial pos="0.0171394 -0.000537591 4.8864e-07"
                        quat="0.411667 0.575338 -0.411094 0.574906" mass="0.085445"
                        diaginertia="5.48211e-05 4.96646e-05 3.57798e-05" />
                      <joint name="right_wrist_roll_joint" pos="0 0 0" axis="1 0 0"
                        range="-1.97222 1.97222" actuatorfrcrange="-25 25" class="arm_motor" />
                      <geom class="visual" mesh="right_wrist_roll_link" rgba="0.7 0.7 0.7 1"/>
                      <geom class="collision" mesh="right_wrist_roll_link"/>
                      <body name="right_wrist_pitch_link" pos="0.038 0 0">
                        <inertial pos="0.0229999 0.00111685 -0.00111658"
                          quat="0.643608 0.293036 0.661363 0.249998" mass="0.48405"
                          diaginertia="0.000430353 0.000429873 0.000164648" />
                        <joint name="right_wrist_pitch_joint" pos="0 0 0" axis="0 1 0"
                          range="-1.61443 1.61443" actuatorfrcrange="-5 5" class="wrist_motor" />
                        <geom class="visual" mesh="right_wrist_pitch_link" rgba="0.7 0.7 0.7 1"/>
                        <geom class="collision" mesh="right_wrist_pitch_link"/>
                        <body name="right_wrist_yaw_link" pos="0.046 0 0">
                          <inertial pos="0.0708244 -0.000191745 0.00161742"
                            quat="0.493188 0.468078 0.526295 0.510571" mass="0.254576"
                            diaginertia="0.000646113 0.000559993 0.000147566" />
                          <joint name="right_wrist_yaw_joint" pos="0 0 0" axis="0 0 1"
                            range="-1.61443 1.61443" actuatorfrcrange="-5 5" class="wrist_motor" />
                          <geom class="visual" mesh="right_wrist_yaw_link" rgba="0.7 0.7 0.7 1"/>
                          <geom class="collision" mesh="right_wrist_yaw_link"/>
                          <geom class="visual" pos="0.0415 -0.003 0" quat="1 0 0 0" mesh="right_rubber_hand" rgba="0.7 0.7 0.7 1"/>
                          <geom class="collision" pos="0.0415 -0.003 0" quat="1 0 0 0" mesh="right_rubber_hand"/>
                        </body>
                      </body>
                    </body>
                  </body>
                </body>
              </body>
            </body>
          </body>
        </body>
      </body>
    </body>
    <body name="box" pos="0.0 0.0 0.0" euler="0 0 0">
      <geom name="box0" pos="0.0 0.0 0.0" size="0.157 0.157 0.157" type="box" rgba="0.25 0.8 0.8 1" class="collision" mass="0.2" condim="6" group="2" friction="0.2 0.012 0.001"/>
      <joint type="slide" axis="1 0 0" limited="false"/>
      <joint type="slide" axis="0 1 0" limited="false"/>
      <joint type="slide" axis="0 0 1" limited="false" />
      <joint type="ball" limited="false"/>
      <body name="bottom_weight0" pos="0.0 0.0 -0.115">
        <geom name="weight0" pos="0.0 0.0 0.0" size="0.05 0.05 0.01" type="box" rgba=".5 .5 .8 0.0" mass="0.3" class="collision" group="2"/>
      </body> 
    </body>

    <body name="box1" pos="0.0 0.0 0.0" euler="0 0 0">
      <geom name="box1" pos="0.0 0.0 0.0" size="0.157 0.157 0.157" type="box" rgba="0.25 0.8 0.25 1" class="collision" mass="0.2" condim="6" group="2" friction="0.2 0.012 0.001"/>
      <joint type="slide" axis="1 0 0" limited="false"/>
      <joint type="slide" axis="0 1 0" limited="false"/>
      <joint type="slide" axis="0 0 1" limited="false" />
      <joint type="ball" limited="false"/>
      <body name="bottom_weight1" pos="0.0 0.0 -0.115">
        <geom name="weight1" pos="0.0 0.0 0.0" size="0.05 0.05 0.01" type="box" rgba=".5 .5 .8 0.0" mass="0.3" class="collision" group="2"/>
      </body> 
    </body>

    <body name="box2" pos="0.0 0.0 0.0" euler="0 0 0">
      <geom name="box2" pos="0.0 0.0 0.0" size="0.157 0.157 0.157" type="box" rgba="0.8 0.8 0.25 1" class="collision" mass="0.2" condim="6" group="2" friction="0.2 0.012 0.001"/>
      <joint type="slide" axis="1 0 0" limited="false"/>
      <joint type="slide" axis="0 1 0" limited="false"/>
      <joint type="slide" axis="0 0 1" limited="false" />
      <joint type="ball" limited="false"/>
      <body name="bottom_weight2" pos="0.0 0.0 -0.115">
        <geom name="weight2" pos="0.0 0.0 0.0" size="0.05 0.05 0.01" type="box" rgba=".5 .5 .8 0.0" mass="0.3" class="collision" group="2"/>
      </body> 
    </body>
  </worldbody>

  <actuator>
    <!-- User parameter is the maximum no-load motor RPM -->
    <motor name="left_hip_pitch" joint="left_hip_pitch_joint" ctrlrange="-88 88" user="3500" />
    <motor name="left_hip_roll" joint="left_hip_roll_joint" ctrlrange="-88 88" user="3500" />
    <motor name="left_hip_yaw" joint="left_hip_yaw_joint" ctrlrange="-88 88" user="3500" />
    <motor name="left_knee" joint="left_knee_joint" ctrlrange="-139 139" user="3000" />
    <motor name="left_ankle_pitch" joint="left_ankle_pitch_joint" ctrlrange="-50 50" user="4000" />
    <motor name="left_ankle_roll" joint="left_ankle_roll_joint" ctrlrange="-50 50" user="4000" />

    <motor name="right_hip_pitch" joint="right_hip_pitch_joint" ctrlrange="-88 88" user="3500" />
    <motor name="right_hip_roll" joint="right_hip_roll_joint" ctrlrange="-88 88" user="3500" />
    <motor name="right_hip_yaw" joint="right_hip_yaw_joint" ctrlrange="-88 88" user="3500" />
    <motor name="right_knee" joint="right_knee_joint" ctrlrange="-139 139" user="3000" />
    <motor name="right_ankle_pitch" joint="right_ankle_pitch_joint" ctrlrange="-50 50" user="4000" />
    <motor name="right_ankle_roll" joint="right_ankle_roll_joint" ctrlrange="-50 50" user="4000" />

    <motor name="waist_yaw" joint="waist_yaw_joint" ctrlrange="-88 88" user="3500" />
    <motor name="waist_roll" joint="waist_roll_joint" ctrlrange="-50 50" user="4000" />
    <motor name="waist_pitch" joint="waist_pitch_joint" ctrlrange="-50 50" user="4000" />

    <motor name="left_shoulder_pitch" joint="left_shoulder_pitch_joint" ctrlrange="-25 25" user="3000" />
    <motor name="left_shoulder_roll" joint="left_shoulder_roll_joint" ctrlrange="-25 25" user="3000" />
    <motor name="left_shoulder_yaw" joint="left_shoulder_yaw_joint" ctrlrange="-25 25" user="3000" />
    <motor name="left_elbow" joint="left_elbow_joint" ctrlrange="-25 25" user="3000" />
    <motor name="left_wrist_roll" joint="left_wrist_roll_joint" ctrlrange="-25 25" user="4000" />
    <motor name="left_wrist_pitch" joint="left_wrist_pitch_joint" ctrlrange="-5 5" user="5000" />
    <motor name="left_wrist_yaw" joint="left_wrist_yaw_joint" ctrlrange="-5 5" user="5000" />

    <motor name="right_shoulder_pitch" joint="right_shoulder_pitch_joint" ctrlrange="-25 25" user="3000" />
    <motor name="right_shoulder_roll" joint="right_shoulder_roll_joint" ctrlrange="-25 25" user="3000" />
    <motor name="right_shoulder_yaw" joint="right_shoulder_yaw_joint" ctrlrange="-25 25" user="3000" />
    <motor name="right_elbow" joint="right_elbow_joint" ctrlrange="-25 25" user="3000" />
    <motor name="right_wrist_roll" joint="right_wrist_roll_joint" ctrlrange="-25 25" user="4000" />
    <motor name="right_wrist_pitch" joint="right_wrist_pitch_joint" ctrlrange="-5 5" user="5000" />
    <motor name="right_wrist_yaw" joint="right_wrist_yaw_joint" ctrlrange="-5 5" user="5000" />
  </actuator>

  <sensor>
    <jointpos name="left_hip_pitch_pos" joint="left_hip_pitch_joint" />
    <jointpos name="left_hip_roll_pos" joint="left_hip_roll_joint" />
    <jointpos name="left_hip_yaw_pos" joint="left_hip_yaw_joint" />
    <jointpos name="left_knee_pos" joint="left_knee_joint" />
    <jointpos name="left_ankle_pitch_pos" joint="left_ankle_pitch_joint" />
    <jointpos name="left_ankle_roll_pos" joint="left_ankle_roll_joint" />
    <jointpos name="right_hip_pitch_pos" joint="right_hip_pitch_joint" />
    <jointpos name="right_hip_roll_pos" joint="right_hip_roll_joint" />
    <jointpos name="right_hip_yaw_pos" joint="right_hip_yaw_joint" />
    <jointpos name="right_knee_pos" joint="right_knee_joint" />
    <jointpos name="right_ankle_pitch_pos" joint="right_ankle_pitch_joint" />
    <jointpos name="right_ankle_roll_pos" joint="right_ankle_roll_joint" />
    <jointpos name="waist_yaw_pos" joint="waist_yaw_joint" />
    <jointpos name="waist_roll_pos" joint="waist_roll_joint" />
    <jointpos name="waist_pitch_pos" joint="waist_pitch_joint" />
    <jointpos name="left_shoulder_pitch_pos" joint="left_shoulder_pitch_joint" />
    <jointpos name="left_shoulder_roll_pos" joint="left_shoulder_roll_joint" />
    <jointpos name="left_shoulder_yaw_pos" joint="left_shoulder_yaw_joint" />
    <jointpos name="left_elbow_pos" joint="left_elbow_joint" />
    <jointpos name="left_wrist_roll_pos" joint="left_wrist_roll_joint" />
    <jointpos name="left_wrist_pitch_pos" joint="left_wrist_pitch_joint" />
    <jointpos name="left_wrist_yaw_pos" joint="left_wrist_yaw_joint" />
    <jointpos name="right_shoulder_pitch_pos" joint="right_shoulder_pitch_joint" />
    <jointpos name="right_shoulder_roll_pos" joint="right_shoulder_roll_joint" />
    <jointpos name="right_shoulder_yaw_pos" joint="right_shoulder_yaw_joint" />
    <jointpos name="right_elbow_pos" joint="right_elbow_joint" />
    <jointpos name="right_wrist_roll_pos" joint="right_wrist_roll_joint" />
    <jointpos name="right_wrist_pitch_pos" joint="right_wrist_pitch_joint" />
    <jointpos name="right_wrist_yaw_pos" joint="right_wrist_yaw_joint" />

    <jointvel name="left_hip_pitch_vel" joint="left_hip_pitch_joint" />
    <jointvel name="left_hip_roll_vel" joint="left_hip_roll_joint" />
    <jointvel name="left_hip_yaw_vel" joint="left_hip_yaw_joint" />
    <jointvel name="left_knee_vel" joint="left_knee_joint" />
    <jointvel name="left_ankle_pitch_vel" joint="left_ankle_pitch_joint" />
    <jointvel name="left_ankle_roll_vel" joint="left_ankle_roll_joint" />
    <jointvel name="right_hip_pitch_vel" joint="right_hip_pitch_joint" />
    <jointvel name="right_hip_roll_vel" joint="right_hip_roll_joint" />
    <jointvel name="right_hip_yaw_vel" joint="right_hip_yaw_joint" />
    <jointvel name="right_knee_vel" joint="right_knee_joint" />
    <jointvel name="right_ankle_pitch_vel" joint="right_ankle_pitch_joint" />
    <jointvel name="right_ankle_roll_vel" joint="right_ankle_roll_joint" />
    <jointvel name="waist_yaw_vel" joint="waist_yaw_joint" />
    <jointvel name="waist_roll_vel" joint="waist_roll_joint" />
    <jointvel name="waist_pitch_vel" joint="waist_pitch_joint" />
    <jointvel name="left_shoulder_pitch_vel" joint="left_shoulder_pitch_joint" />
    <jointvel name="left_shoulder_roll_vel" joint="left_shoulder_roll_joint" />
    <jointvel name="left_shoulder_yaw_vel" joint="left_shoulder_yaw_joint" />
    <jointvel name="left_elbow_vel" joint="left_elbow_joint" />
    <jointvel name="left_wrist_roll_vel" joint="left_wrist_roll_joint" />
    <jointvel name="left_wrist_pitch_vel" joint="left_wrist_pitch_joint" />
    <jointvel name="left_wrist_yaw_vel" joint="left_wrist_yaw_joint" />
    <jointvel name="right_shoulder_pitch_vel" joint="right_shoulder_pitch_joint" />
    <jointvel name="right_shoulder_roll_vel" joint="right_shoulder_roll_joint" />
    <jointvel name="right_shoulder_yaw_vel" joint="right_shoulder_yaw_joint" />
    <jointvel name="right_elbow_vel" joint="right_elbow_joint" />
    <jointvel name="right_wrist_roll_vel" joint="right_wrist_roll_joint" />
    <jointvel name="right_wrist_pitch_vel" joint="right_wrist_pitch_joint" />
    <jointvel name="right_wrist_yaw_vel" joint="right_wrist_yaw_joint" />

    <jointactuatorfrc name="left_hip_pitch_torque" joint="left_hip_pitch_joint" />
    <jointactuatorfrc name="left_hip_roll_torque" joint="left_hip_roll_joint" />
    <jointactuatorfrc name="left_hip_yaw_torque" joint="left_hip_yaw_joint" />
    <jointactuatorfrc name="left_knee_torque" joint="left_knee_joint" />
    <jointactuatorfrc name="left_ankle_pitch_torque" joint="left_ankle_pitch_joint" />
    <jointactuatorfrc name="left_ankle_roll_torque" joint="left_ankle_roll_joint" />
    <jointactuatorfrc name="right_hip_pitch_torque" joint="right_hip_pitch_joint" />
    <jointactuatorfrc name="right_hip_roll_torque" joint="right_hip_roll_joint" />
    <jointactuatorfrc name="right_hip_yaw_torque" joint="right_hip_yaw_joint" />
    <jointactuatorfrc name="right_knee_torque" joint="right_knee_joint" />
    <jointactuatorfrc name="right_ankle_pitch_torque" joint="right_ankle_pitch_joint" />
    <jointactuatorfrc name="right_ankle_roll_torque" joint="right_ankle_roll_joint" />
    <jointactuatorfrc name="waist_yaw_torque" joint="waist_yaw_joint" />
    <jointactuatorfrc name="waist_roll_torque" joint="waist_roll_joint" />
    <jointactuatorfrc name="waist_pitch_torque" joint="waist_pitch_joint" />
    <jointactuatorfrc name="left_shoulder_pitch_torque" joint="left_shoulder_pitch_joint" />
    <jointactuatorfrc name="left_shoulder_roll_torque" joint="left_shoulder_roll_joint" />
    <jointactuatorfrc name="left_shoulder_yaw_torque" joint="left_shoulder_yaw_joint" />
    <jointactuatorfrc name="left_elbow_torque" joint="left_elbow_joint" />
    <jointactuatorfrc name="left_wrist_roll_torque" joint="left_wrist_roll_joint" />
    <jointactuatorfrc name="left_wrist_pitch_torque" joint="left_wrist_pitch_joint" />
    <jointactuatorfrc name="left_wrist_yaw_torque" joint="left_wrist_yaw_joint" />
    <jointactuatorfrc name="right_shoulder_pitch_torque" joint="right_shoulder_pitch_joint" />
    <jointactuatorfrc name="right_shoulder_roll_torque" joint="right_shoulder_roll_joint" />
    <jointactuatorfrc name="right_shoulder_yaw_torque" joint="right_shoulder_yaw_joint" />
    <jointactuatorfrc name="right_elbow_torque" joint="right_elbow_joint" />
    <jointactuatorfrc name="right_wrist_roll_torque" joint="right_wrist_roll_joint" />
    <jointactuatorfrc name="right_wrist_pitch_torque" joint="right_wrist_pitch_joint" />
    <jointactuatorfrc name="right_wrist_yaw_torque" joint="right_wrist_yaw_joint" />

    <framequat name="imu_quat" objtype="site" objname="imu" />
    <gyro name="pelvis/imu-gyro" site="imu" />
    <accelerometer name="imu_acc" site="imu" />

    <framepos name="frame_pos" objtype="site" objname="imu" />
    <framelinvel name="frame_vel" objtype="site" objname="imu" />

    <framequat name="secondary_imu_quat" objtype="site" objname="secondary_imu" />
    <gyro name="secondary_imu_gyro" site="secondary_imu" noise="5e-4" cutoff="34.9"/>
    <accelerometer name="secondary_imu_acc" site="secondary_imu" noise="1e-2" cutoff="157"/>
  </sensor>

</mujoco>